Workbook

Sheet 18O Option 1
A2: lit | B2: unc lit | C2: SF re-norm to lit | D2: unc re-norm to lit | G2: SF | H2: unc | I2: unc final | J2: chi2 | K2: chi2/ndf | L2: comment
A3: 1.22 | B3: =A3*0.15 -> 0.183 | C3: =G3*$A$5/$G$5 -> 1.0456082 | D3: =I3*$A$5/$G$5 -> 0.14268404 | E3: 0.0 (0+) | F3: 0d5/2, 0+ | G3: 6.19606 | H3: 0.509265 | I3: =H3*SQRT(K3) -> 0.84551641 | J3: 8.26947 | K3: 2.75649 | L3: free fit
A4: 0.21 | B4: =A4*0.15 -> 0.0315 | C4: =G4*$A$5/$G$5 -> 0.12542688 | D4: =I4*$A$5/$G$5 -> 0.018085587 | E4: 1.982 (2+) | F4: 1s1/2, 2+ | G4: 0.743254 | H4: 0.0949108 | I4: =H4*SQRT(K4) -> 0.10717148 | J4: 10.2004 | K4: 1.27505 | L4: free fit
A5: 0.83 | B5: =A5*0.15 -> 0.1245 | C5: =G5*$A$5/$G$5 -> 0.83 | D5: =I5*$A$5/$G$5 -> 0.041252741 | F5: 0d5/2, 2+ | G5: 4.91841 | H5: 0.216489 | I5: =H5*SQRT(K5) -> 0.24445529 | J5: 10.2004 | K5: 1.27505
A6: =1.57+0.28 -> 1.85 | B6: =A6*0.15 -> 0.2775 | C6: =G6*$A$5/$G$5 -> 1.4229668 | D6: =I6*$A$5/$G$5 -> 0.078770001 | E6: 3.552 (4+) 3.620 (0+) | F6: 0d5/2, 4+ | G6: 8.43221 | H6: 0.147797 | I6: =H6*SQRT(K6) -> 0.46677489 | J6: 69.8203 | K6: 9.97433 | L6: both 4+ and 0+ are d-waves, fitted with DWBA calculation for the mean energy of the doublet and only 4+ | T6: what to do about lit SF for this state?
A7: 0.35 | B7: =A7*0.15 -> 0.0525 | C7: =G7*$A$5/$G$5 -> 0.21349709 | D7: =I7*$A$5/$G$5 -> 0.073709224 | E7: 3.920 (2+) | F7: 1s1/2, 2+ | G7: 1.26514 | H7: 0.160803 | I7: =H7*SQRT(K7) -> 0.43678576 | J7: 44.267 | K7: 7.37817 | L7: free fit
A8: 0.66 | B8: =A8*0.15 -> 0.099 | C8: =G8*$A$5/$G$5 -> 0.58829067 | D8: =I8*$A$5/$G$5 -> 0.092993819 | F8: 0d5/2, 2+ | G8: 3.48609 | H8: 0.202874 | I8: =H8*SQRT(K8) -> 0.55106233 | J8: 44.267 | K8: 7.37817
A9: =0.16 -> 0.16 | B9: =A9*0.15 -> 0.024 | C9: =G9*$A$5/$G$5 -> 0.48841715 | D9: =I9*$A$5/$G$5 -> 0.25915031 | E9: 5.255 (2+) 5.340 (0+) 5.375 (3+) | F9: 0d5/2, 0+ | G9: 2.89426 | H9: 1.47686 | I9: =H9*SQRT(K9) -> 1.5356717 | J9: 4.32492 | K9: 1.08123 | L9: 2+ and 3+ are s-waves and I took only the 3+ (SF in the literature is higher for that one)
A10: 1.36 | B10: =A10*0.15 -> 0.204 | C10: =G10*$A$5/$G$5 -> 0.8322208 | D10: =I10*$A$5/$G$5 -> 0.083538889 | F10: 1s1/2, 3+ | G10: 4.93157 | H10: 0.476076 | I10: =H10*SQRT(K10) -> 0.49503435 | J10: 4.32492 | K10: 1.08123
A11: 0.03 | B11: =A11*0.15 -> 0.0045 | C11: =G11*$A$5/$G$5 -> 0.048557703 | D11: =I11*$A$5/$G$5 -> 0.01196321 | E11: 6.200 (1-) | F11: 1p3/2, 1- | G11: 0.287743 | H11: 0.0363742 | I11: =H11*SQRT(K11) -> 0.070891533 | J11: 15.1936 | K11: 3.79841 | L11: free fit
A12: 0.03 | B12: =A12*0.15 -> 0.0045 | C12: =G12*$A$5/$G$5 -> 0.047533199 | D12: =I12*$A$5/$G$5 -> 0.0087477874 | E12: 7.1 (4+) | F12: 0d5/2, 4+ | G12: 0.281672 | H12: 0.022748 | I12: =H12*SQRT(K12) -> 0.051837596 | J12: 15.5784 | K12: 5.19282 | L12: free fit

Sheet 18O Option 2 lit
A2: lit | B2: unc lit | C2: SF re-norm to lit | D2: unc re-norm to lit | G2: SF | H2: unc | I2: unc final | J2: chi2 | K2: chi2/ndf | L2: lit ratio | M2: unc. Lit | N2: norm | O2: unc norm | P2: unc inflated | Q2: comment | S2: SF *
A3: 1.22 | B3: =A3*0.15 -> 0.183 | C3: =G3*$A$5/$G$5 -> 1.0456082 | D3: =I3*$A$5/$G$5 -> 0.14268404 | E3: 0.0 (0+) | F3: 0d5/2, 0+ | G3: ='18O Option 1'!G3 -> 6.19606 | H3: ='18O Option 1'!H3 -> 0.509265 | I3: =H3*SQRT(K3) -> 0.84551641 | J3: ='18O Option 1'!J3 -> 8.26947 | K3: ='18O Option 1'!K3 -> 2.75649 | P3: =H3*SQRT(K3) -> 0.84551641 | Q3: free fit | S3: =G3*$S$21/$G$5 -> 1.5478781
A4: 0.21 | B4: =A4*0.15 -> 0.0315 | C4: =G4*$A$5/$G$5 -> 0.12542688 | D4: =I4*$A$5/$G$5 -> 0.018085587 | E4: 1.982 (2+) | F4: 1s1/2, 2+ | G4: ='18O Option 1'!G4 -> 0.743254 | H4: ='18O Option 1'!H4 -> 0.0949108 | I4: =H4*SQRT(K4) -> 0.10717148 | J4: ='18O Option 1'!J4 -> 10.2004 | K4: ='18O Option 1'!K4 -> 1.27505 | P4: =H4*SQRT(K4) -> 0.10717148 | Q4: free fit | S4: =G4*$S$21/$G$5 -> 0.18567712
A5: 0.83 | B5: =A5*0.15 -> 0.1245 | C5: =G5*$A$5/$G$5 -> 0.83 | D5: =I5*$A$5/$G$5 -> 0.041252741 | F5: 0d5/2, 2+ | G5: ='18O Option 1'!G5 -> 4.91841 | H5: ='18O Option 1'!H5 -> 0.216489 | I5: =H5*SQRT(K5) -> 0.24445529 | J5: ='18O Option 1'!J5 -> 10.2004 | K5: ='18O Option 1'!K5 -> 1.27505 | P5: =H5*SQRT(K5) -> 0.24445529 | S5: =G5*$S$21/$G$5 -> 1.2287
A6: 1.57 | B6: =A6*0.15 -> 0.2355 | C6: =G6*$A$5/$G$5 -> 1.3953268 | D6: =I6*$A$5/$G$5 -> 0.22309649 | E6: 3.552 (4+) | F6: 0d5/2, 4+ | G6: =L6*N6 -> 8.2684207 | H6: =L6*O6 -> 0.1449256 | I6: =G6*SQRT(POWER((P6/N6),2)+POWER((M6/L6),2)) -> 1.3220241 | J6: 69.8203 | K6: 9.97433 | L6: 1.57 | M6: =0.15*L6 -> 0.2355 | N6: 5.26651 | O6: 0.0923093 | P6: =O6*SQRT(K6) -> 0.29153273 | S6: =G6*$S$21/$G$5 -> 2.065588
A7: 0.28 | B7: =A7*0.15 -> 0.042 | C7: =G7*$A$5/$G$5 -> 0.24884809 | D7: =I7*$A$5/$G$5 -> 0.039787909 | E7: 3.630 (0+) | F7: 0d5/2, 0+ | G7: =L7*N7 -> 1.4746228 | H7: =L7*O7 -> 0.025846604 | I7: =G7*SQRT(POWER((P7/N7),2)+POWER((M7/L7),2)) -> 0.235775 | J7: 69.8203 | K7: 9.97433 | L7: 0.28 | M7: =0.15*L7 -> 0.042 | N7: 5.26651 | O7: 0.0923093 | P7: =O7*SQRT(K7) -> 0.29153273 | S7: =G7*$S$21/$G$5 -> 0.36838512
A8: 0.35 | B8: =A8*0.15 -> 0.0525 | C8: =G8*$A$5/$G$5 -> 0.21349709 | D8: =I8*$A$5/$G$5 -> 0.073709224 | E8: 3.920 (2+) | F8: 1s1/2, 2+ | G8: ='18O Option 1'!G7 -> 1.26514 | H8: ='18O Option 1'!H7 -> 0.160803 | I8: =H8*SQRT(K8) -> 0.43678576 | J8: ='18O Option 1'!J7 -> 44.267 | K8: ='18O Option 1'!K7 -> 7.37817 | P8: =H8*SQRT(K8) -> 0.43678576 | Q8: free fit | S8: =G8*$S$21/$G$5 -> 0.31605285
A9: 0.66 | B9: =A9*0.15 -> 0.099 | C9: =G9*$A$5/$G$5 -> 0.58829067 | D9: =I9*$A$5/$G$5 -> 0.092993819 | F9: 0d5/2, 2+ | G9: ='18O Option 1'!G8 -> 3.48609 | H9: ='18O Option 1'!H8 -> 0.202874 | I9: =H9*SQRT(K9) -> 0.55106233 | J9: ='18O Option 1'!J8 -> 44.267 | K9: ='18O Option 1'!K8 -> 7.37817 | P9: =H9*SQRT(K9) -> 0.55106233 | S9: =G9*$S$21/$G$5 -> 0.87088282
A10: 0.35 | B10: =A10*0.15 -> 0.0525 | C10: =G10*$A$5/$G$5 -> 0.26199226 | D10: =I10*$A$5/$G$5 -> 0.040914961 | E10: 5.255 (2+) | F10: 1s1/2, 2+ | G10: =L10*N10 -> 1.5525125 | H10: =L10*O10 -> 0.05833625 | I10: =G10*SQRT(POWER((P10/N10),2)+POWER((M10/L10),2)) -> 0.24245368 | J10: 6.68822 | K10: 1.33764 | L10: 0.35 | M10: =0.15*L10 -> 0.0525 | N10: 4.43575 | O10: 0.166675 | P10: =O10*SQRT(K10) -> 0.19277028 | S10: =G10*$S$21/$G$5 -> 0.38784325
A11: 0.16 | B11: =A11*0.15 -> 0.024 | C11: =G11*$A$5/$G$5 -> 0.11976789 | D11: =I11*$A$5/$G$5 -> 0.018703982 | E11: 5.340 (0+) | F11: 0d5/2, 0+ | G11: =L11*N11 -> 0.70972 | H11: =L11*O11 -> 0.026668 | I11: =G11*SQRT(POWER((P11/N11),2)+POWER((M11/L11),2)) -> 0.11083597 | J11: 6.68822 | K11: 1.33764 | L11: 0.16 | M11: =0.15*L11 -> 0.024 | N11: 4.43575 | O11: 0.166675 | P11: =O11*SQRT(K11) -> 0.19277028 | S11: =G11*$S$21/$G$5 -> 0.17729977
A12: 1.01 | B12: =A12*0.15 -> 0.1515 | C12: =G12*$A$5/$G$5 -> 0.75603482 | D12: =I12*$A$5/$G$5 -> 0.11806889 | E12: 5.375 (3+) | F12: 1s1/2, 3+ | G12: =L12*N12 -> 4.4801075 | H12: =L12*O12 -> 0.16834175 | I12: =G12*SQRT(POWER((P12/N12),2)+POWER((M12/L12),2)) -> 0.69965204 | J12: 6.68822 | K12: 1.33764 | L12: 1.01 | M12: =0.15*L12 -> 0.1515 | N12: 4.43575 | O12: 0.166675 | P12: =O12*SQRT(K12) -> 0.19277028 | S12: =G12*$S$21/$G$5 -> 1.1192048
A13: 0.03 | B13: =A13*0.15 -> 0.0045 | C13: =G13*$A$5/$G$5 -> 0.048557703 | D13: =I13*$A$5/$G$5 -> 0.01196321 | E13: 6.200 (1-) | F13: 1p3/2, 1- | G13: ='18O Option 1'!G11 -> 0.287743 | H13: ='18O Option 1'!H11 -> 0.0363742 | I13: =H13*SQRT(K13) -> 0.070891533 | J13: ='18O Option 1'!J11 -> 15.1936 | K13: ='18O Option 1'!K11 -> 3.79841 | P13: =H13*SQRT(K13) -> 0.070891533 | Q13: free fit | S13: =G13*$S$21/$G$5 -> 0.071882951
A14: 0.03 | B14: =A14*0.15 -> 0.0045 | C14: =G14*$A$5/$G$5 -> 0.047533199 | D14: =I14*$A$5/$G$5 -> 0.0087477874 | E14: 7.1 (4+) | F14: 0d5/2, 4+ | G14: ='18O Option 1'!G12 -> 0.281672 | H14: ='18O Option 1'!H12 -> 0.022748 | I14: =H14*SQRT(K14) -> 0.051837596 | J14: ='18O Option 1'!J12 -> 15.5784 | K14: ='18O Option 1'!K12 -> 5.19282 | P14: =H14*SQRT(K14) -> 0.051837596 | Q14: free fit | S14: =G14*$S$21/$G$5 -> 0.070366315
S20: SM (i) for 1.982 (1st 2+)
S21: 1.2287

Sheet 18O Option 2 SM
D2: SF | E2: unc | F2: unc * sqrt(chi2/ndf) | G2: chi2 | H2: chi2/ndf | I2: SM ratio | J2: norm | K2: unc | L2: comment
B3: 0.0 (0+) | C3: 0d5/2, 0+ | D3: ='18O Option 1'!G3 -> 6.19606 | E3: ='18O Option 1'!H3 -> 0.509265 | F3: ='18O Option 1'!I3 -> 0.84551641 | G3: ='18O Option 1'!J3 -> 8.26947 | H3: ='18O Option 1'!K3 -> 2.75649 | L3: free fit
B4: 1.982 (2+) | C4: 1s1/2, 2+ | D4: ='18O Option 1'!G4 -> 0.743254 | E4: ='18O Option 1'!H4 -> 0.0949108 | F4: ='18O Option 1'!I4 -> 0.10717148 | G4: ='18O Option 1'!J4 -> 10.2004 | H4: ='18O Option 1'!K4 -> 1.27505 | L4: free fit
C5: 0d5/2, 2+ | D5: ='18O Option 1'!G5 -> 4.91841 | E5: ='18O Option 1'!H5 -> 0.216489 | F5: ='18O Option 1'!I5 -> 0.24445529 | G5: ='18O Option 1'!J5 -> 10.2004 | H5: ='18O Option 1'!K5 -> 1.27505
B6: 3.552 (4+) | C6: 0d5/2, 4+ | D6: =I6*J6 -> 8.601854 | E6: 0.13732075 | G6: 89.2311 | H6: 12.7473 | I6: 1.8598 | J6: 4.62515 | K6: 0.0738363
B7: 3.630 (0+) | C7: 0d5/2, 0+ | D7: =I7*J7 -> 1.5017862 | E7: 0.023974647 | G7: 89.2311 | H7: 12.7473 | I7: 0.3247 | J7: 4.62515 | K7: 0.0738363
B8: 3.920 (2+) | C8: 1s1/2, 2+ | D8: ='18O Option 1'!G7 -> 1.26514 | E8: ='18O Option 1'!H7 -> 0.160803 | F8: ='18O Option 1'!I7 -> 0.43678576 | G8: ='18O Option 1'!J7 -> 44.267 | H8: ='18O Option 1'!K7 -> 7.37817 | L8: free fit
C9: 0d5/2, 2+ | D9: ='18O Option 1'!G8 -> 3.48609 | E9: ='18O Option 1'!H8 -> 0.202874 | F9: ='18O Option 1'!I8 -> 0.55106233 | G9: ='18O Option 1'!J8 -> 44.267 | H9: ='18O Option 1'!K8 -> 7.37817
B10: 5.255 (2+) | C10: 1s1/2, 2+ | D10: =I10*J10 -> 0.03459645 | E10: =I10*K10 -> 0.001432155 | G10: 45.5204 | H10: 9.10409 | I10: 0.015 | J10: 2.30643 | K10: 0.095477
C11: 0d3/2, 2+ | D11: =I11*J11 -> 2.0605646 | E11: =I11*K11 -> 0.085299152 | G11: 45.5204 | H11: 9.10409 | I11: 0.8934 | J11: 2.30643 | K11: 0.095477
C12: 0d5/2, 2+ | D12: =I12*J12 -> 0.0230643 | E12: =I12*K12 -> 0.00095477 | G12: 45.5204 | H12: 9.10409 | I12: 0.01 | J12: 2.30643 | K12: 0.095477
B13: 5.340 (0+) | C13: 0d5/2, 0+ | D13: =I13*J13 -> 0.30121976 | E13: =I13*K13 -> 0.012469296 | G13: 45.5204 | H13: 9.10409 | I13: 0.1306 | J13: 2.30643 | K13: 0.095477
B14: 5.375 (3+) | C14: 1s1/2, 3+ | D14: =I14*J14 -> 2.2833657 | E14: =I14*K14 -> 0.09452223 | G14: 45.5204 | H14: 9.10409 | I14: 0.99 | J14: 2.30643 | K14: 0.095477
B15: 6.200 (1-) | C15: 1p3/2, 1- | D15: ='18O Option 1'!G11 -> 0.287743 | E15: ='18O Option 1'!H11 -> 0.0363742 | F15: ='18O Option 1'!I11 -> 0.070891533 | G15: ='18O Option 1'!J11 -> 15.1936 | H15: ='18O Option 1'!K11 -> 3.79841 | L15: free fit
B16: 7.1 (4+) | C16: 0d5/2, 4+ | D16: ='18O Option 1'!G12 -> 0.281672 | E16: ='18O Option 1'!H12 -> 0.022748 | F16: ='18O Option 1'!I12 -> 0.051837596 | G16: ='18O Option 1'!J12 -> 15.5784 | H16: ='18O Option 1'!K12 -> 5.19282 | L16: free fit
B18: This uses the USDi interaction. Some states are not reproduced or messed up (marked with red)

Sheet 18F norm Option 1
A2: lit | B2: unc lit | C2: SF re-norm to lit | D2: unc re-norm to lit | G2: SF | H2: SF norm | I2: unc fit | J2: unc final | K2: chi2 | L2: chi2/ndf | M2: unc inflated | N2: comment
C3: =H3*A$7/H$7 -> 0.93727304 | D3: =J3*A$7/H$7 -> 0.16236841 | E3: 0.0 | F3: 0d3/2, 1+ | G3: 2.2913 | H3: =G3*$G$23 -> 7.4353114 | I3: 0.190598 | J3: =H3*SQRT(POWER(($H$23/$G$23),2)+POWER((M3/G3),2)) -> 1.2880555 | K3: 2.36101 | L3: 0.787003 | M3: =I3 -> 0.190598 | N3: free fit | Q3: =J3/H3 -> 0.17323491
A4: 0.102 | B4: =0.2*A4 -> 0.0204 | C4: =H4*A$7/H$7 -> 0.031968034 | D4: =J4*A$7/H$7 -> 0.11706196 | E4: 0.937 (3+) 1.042 (0+) | F4: 1s1/2, 3+ | G4: 0.0781505 | H4: =G4*$G$23 -> 0.25359984 | I4: 0.100659 | J4: =H4*SQRT(POWER(($H$23/$G$23),2)+POWER((M4/G4),2)) -> 0.92864307 | K4: 80.6881 | L4: 8.06881 | M4: =I4*SQRT(L4) -> 0.28592844 | Q4: =J4/H4 -> 3.6618441
A5: =0.306+0.96+0.89 -> 2.156 | B5: =0.2*A5 -> 0.4312 | C5: =H5*A$7/H$7 -> 1.8565557 | D5: =J5*A$7/H$7 -> 0.56335248 | E5: 1.121 (5+) | F5: 0d5/2, 5+ | G5: 4.53862 | H5: =G5*$G$23 -> 14.727907 | I5: 0.419658 | J5: =H5*SQRT(POWER(($H$23/$G$23),2)+POWER((M5/G5),2)) -> 4.4690298 | K5: 80.6881 | L5: 8.06881 | M5: =I5*SQRT(L5) -> 1.1920659 | Q5: =J5/H5 -> 0.30343958
A6: 0.21 | B6: =0.2*A6 -> 0.042 | C6: =H6*A$7/H$7 -> 0.063662409 | D6: =J6*A$7/H$7 -> 0.039924694 | E6: 3.062 (2+) | F6: 1s1/2, 2+ | G6: 0.155632 | H6: =G6*$G$23 -> 0.50502876 | I6: 0.0542378 | J6: =H6*SQRT(POWER(($H$23/$G$23),2)+POWER((M6/G6),2)) -> 0.31671938 | K6: 24.3851 | L6: 3.04813 | M6: =I6*SQRT(L6) -> 0.094693203 | N6: free fit | Q6: =J6/H6 -> 0.62713138
A7: 0.62 | B7: =0.2*A7 -> 0.124 | C7: =H7*A$7/H$7 -> 0.62 | D7: =O7*A$7/H$7 -> 0.12962513 | F7: 0d5/2, 2+ | G7: 1.51568 | H7: =G7*$G$23 -> 4.91841 | I7: 0.124664 | J7: =I7*SQRT(L7) -> 0.21764956 | K7: 24.3851 | L7: 3.04813 | M7: =I7*SQRT(L7) -> 0.21764956 | O7: =H7*SQRT(POWER(($H$23/$G$23),2)+POWER((M7/G7),2)) -> 1.0283057 | Q7: =O7/H7 -> 0.20907278
C8: =H8*A$7/H$7 -> 0.28447523 | D8: =J8*A$7/H$7 -> 0.06250543 | E8: 3.727 (1+) 3.839 (2+) | F8: 1s1/2, 2+ | G8: 0.695441 | H8: =G8*$G$23 -> 2.2567191 | I8: 0.110369 | J8: =H8*SQRT(POWER(($H$23/$G$23),2)+POWER((M8/G8),2)) -> 0.49585054 | K8: 3.20376 | L8: 0.457679 | M8: =I8 -> 0.110369 | Q8: =J8/H8 -> 0.21972187
C9: =H9*A$7/H$7 -> 0.56663438 | D9: =J9*A$7/H$7 -> 0.12048062 | F9: 0d5/2, 2+ | G9: 1.38522 | H9: =G9*$G$23 -> 4.4950649 | I9: 0.206014 | J9: =H9*SQRT(POWER(($H$23/$G$23),2)+POWER((M9/G9),2)) -> 0.95576303 | K9: 3.20376 | L9: 0.457679 | M9: =I9 -> 0.206014 | Q9: =J9/H9 -> 0.21262497
A10: 0.17 | B10: =0.2*A10 -> 0.034 | C10: =H10*A$7/H$7 -> 0.14737313 | D10: =J10*A$7/H$7 -> 0.049414499 | E10: 4.115 (3+) | F10: 1s1/2, 3+ | G10: 0.360275 | H10: =G10*$G$23 -> 1.1690991 | I10: 0.0693713 | J10: =H10*SQRT(POWER(($H$23/$G$23),2)+POWER((M10/G10),2)) -> 0.39200124 | K10: 14.4574 | L10: 2.40956 | M10: =I10*SQRT(L10) -> 0.10768339 | N10: free fit | Q10: =J10/H10 -> 0.33530197
A11: 0.68 | B11: =0.2*A11 -> 0.136 | C11: =H11*A$7/H$7 -> 0.77927056 | D11: =J11*A$7/H$7 -> 0.13982175 | F11: 0d5/2, 3+ | G11: 1.90504 | H11: =G11*$G$23 -> 6.1818905 | I11: 0.117092 | J11: =H11*SQRT(POWER(($H$23/$G$23),2)+POWER((M11/G11),2)) -> 1.1091947 | K11: 14.4574 | L11: 2.40956 | M11: =I11*SQRT(L11) -> 0.18175907 | Q11: =J11/H11 -> 0.17942645
A12: 0.074 | B12: =0.2*A12 -> 0.0148 | C12: =H12*A$7/H$7 -> 0.17371969 | D12: =J12*A$7/H$7 -> 0.058351436 | E12: 4.360 (1+) | F12: 0d5/2, 1+ | G12: 0.424683 | H12: =G12*$G$23 -> 1.3781043 | I12: 0.085519 | J12: =H12*SQRT(POWER(($H$23/$G$23),2)+POWER((M12/G12),2)) -> 0.46289724 | K12: 11.0645 | L12: 2.2129 | M12: =I12*SQRT(L12) -> 0.12721652 | N12: free fit | Q12: =J12/H12 -> 0.3358942
A13: 1.22 | B13: =0.2*A13 -> 0.244 | C13: =H13*A$7/H$7 -> 0.90132099 | D13: =J13*A$7/H$7 -> 0.15989919 | E13: 4.652 (4+) 4.753 (0+) | F13: 0d5/2, 4+ | G13: 2.20341 | H13: =G13*$G$23 -> 7.1501067 | I13: 0.0715569 | J13: =H13*SQRT(POWER(($H$23/$G$23),2)+POWER((M13/G13),2)) -> 1.2684674 | K13: 55.6318 | L13: 7.9474 | M13: =I13*SQRT(L13) -> 0.20172701 | Q13: =J13/H13 -> 0.17740537
A14: 0.17 | B14: =0.2*A14 -> 0.034 | C14: =H14*A$7/H$7 -> 0.15681294 | D14: =J14*A$7/H$7 -> 0.062524696 | E14: 4.964 (2+) | F14: 1s1/2, 2+ | G14: 0.383352 | H14: =G14*$G$23 -> 1.2439844 | I14: 0.0931427 | J14: =H14*SQRT(POWER(($H$23/$G$23),2)+POWER((M14/G14),2)) -> 0.49600337 | K14: 13.8112 | L14: 2.30186 | M14: =I14*SQRT(L14) -> 0.141315 | N14: free fit | Q14: =J14/H14 -> 0.39872153
A15: 0.51 | B15: =0.2*A15 -> 0.102 | C15: =H15*A$7/H$7 -> 0.47113995 | D15: =J15*A$7/H$7 -> 0.10209211 | F15: 0d5/2, 2+ | G15: 1.15177 | H15: =G15*$G$23 -> 3.7375152 | I15: 0.117274 | J15: =H15*SQRT(POWER(($H$23/$G$23),2)+POWER((M15/G15),2)) -> 0.80988844 | K15: 13.8112 | L15: 2.30186 | M15: =I15*SQRT(L15) -> 0.17792673 | Q15: =J15/H15 -> 0.21669168
E16: 6.136 (0+) | F16: 0d5/2, 0+ | G16: 0 | H16: =G16*$G$23 -> 0 | I16: 0.76793 | K16: 8.15518 | L16: 2.03879 | M16: =I16*SQRT(L16) -> 1.0964981 | Q16: =J16/H16 -> #DIV/0!
E17: 6.163 (3+) | F17: 1s1/2, 3+ | G17: 2.44 | H17: =G17*$G$23 -> 7.9178457 | I17: 0.278062 | J17: =H17*SQRT(POWER(($H$23/$G$23),2)+POWER((M17/G17),2)) -> 1.7628246 | K17: 8.15518 | L17: 2.03879 | M17: =I17*SQRT(L17) -> 0.39703417 | Q17: =J17/H17 -> 0.22263942
E18: 6.286 | F18: 1s1/2, 2+ | G18: 0 | H18: =G18*$G$23 -> 0 | M18: =I18*SQRT(L18) -> 0 | Q18: =J18/H18 -> #DIV/0!
E19: some state | F19: 1p3/2, 3- | G19: 0.26 | H19: =G19*$G$23 -> 0.84370487 | M19: =I19*SQRT(L19) -> 0 | Q19: =J19/H19 -> 0
E20: 6.633 6.643 | F20: 1f7/2, 2- | G20: 0.804098 | H20: =G20*$G$23*G28 -> 3.6530383 | I20: 0.103809 | J20: =H20*SQRT(POWER((H$23/G$23),2)+POWER((M20/G20),2)+POWER((H28/G28),2)) -> 0.79755575 | K20: 1.25024 | L20: 0.250049 | M20: =I20*SQRT(L20) -> 0.051909586 | Q20: =J20/H20 -> 0.21832669
G22: norm factor 2 | H22: unc norm factor
G23: ='18O Option 1'!G5/G7 -> 3.2450187 | H23: =G23*SQRT(POWER(('18O Option 1'!I5/'18O Option 1'!G5),2)+POWER(('18F norm Option 1'!J7/'18F norm Option 1'!G7),2)) -> 0.4931026
G24: SF free fit
G27: epsilon | H27: unc eps
G28: 1.4 | H28: 0.2

Sheet 18F norm Option 2 lit
A2: unc/SF | B2: lit | C2: unc lit | D2: SF re-norm to lit | E2: unc re-norm to lit | H2: SF | I2: SF norm | J2: unc fit | K2: unc final | L2: chi2 | M2: chi2/ndf | N2: lit ratio | O2: unc. Lit | P2: norm | Q2: unc norm | R2: unc norm inflated | S2: comment
A3: =E3/D3 -> 0.17323491 | D3: =I3*$B$9/$I$9 -> 0.93727304 | E3: =K3*$B$9/$I$9 -> 0.16236841 | F3: 0.0 | G3: 0d3/2, 1+ | H3: ='18F norm Option 1'!G3 -> 2.2913 | I3: ='18F norm Option 1'!H3 -> 7.4353114 | J3: ='18F norm Option 1'!I3 -> 0.190598 | K3: ='18F norm Option 1'!J3 -> 1.2880555 | L3: ='18F norm Option 1'!K3 -> 2.36101 | M3: ='18F norm Option 1'!L3 -> 0.787003 | S3: free fit | X3: =K3/I3 -> 0.17323491
A4: =E4/D4 -> 0.28198184 | B4: 0.102 | C4: =0.2*B4 -> 0.0204 | D4: =I4*$B$9/$I$9 -> 0.12893044 | E4: =K4*$B$9/$I$9 -> 0.036356044 | F4: 0.937 (3+) | G4: 1s1/2, 3+ | H4: =N4*P4 -> 0.31518918 | I4: =H4*$H$29 -> 1.0227948 | K4: =I4*SQRT(POWER(($I$29/$H$29),2)+POWER((R4/P4),2)+POWER((O4/N4),2)) -> 0.28840956 | L4: 86.3717 | M4: 7.85197 | N4: 0.102 | O4: =0.2*N4 -> 0.0204 | P4: 3.09009 | Q4: 0.141321 | R4: =Q4*SQRT(M4) -> 0.39600076 | X4: =K4/I4 -> 0.28198184
A5: =E5/D5 -> 0.28198184 | B5: 0.306 | C5: =0.2*B5 -> 0.0612 | D5: =I5*$B$9/$I$9 -> 0.38679132 | E5: =K5*$B$9/$I$9 -> 0.10906813 | G5: 1d5/2, 3+ | H5: =N5*P5 -> 0.94556754 | I5: =H5*$H$29 -> 3.0683844 | K5: =I5*SQRT(POWER(($I$29/$H$29),2)+POWER((R5/P5),2)+POWER((O5/N5),2)) -> 0.86522869 | L5: 86.3717 | M5: 7.85197 | N5: 0.306 | O5: =0.2*N5 -> 0.0612 | P5: 3.09009 | Q5: 0.141321 | R5: =Q5*SQRT(M5) -> 0.39600076 | X5: =K5/I5 -> 0.28198184
A6: =E6/D6 -> 0.28198184 | B6: 0.96 | C6: =0.2*B6 -> 0.192 | D6: =I6*$B$9/$I$9 -> 1.213463 | E6: =K6*$B$9/$I$9 -> 0.34217453 | F6: 1.042 (0+) | G6: 0d5/2, 0+ | H6: =N6*P6 -> 2.9664864 | I6: =H6*$H$29 -> 9.626304 | K6: =I6*SQRT(POWER(($I$29/$H$29),2)+POWER((R6/P6),2)+POWER((O6/N6),2)) -> 2.7144429 | L6: 86.3717 | M6: 7.85197 | N6: 0.96 | O6: =0.2*N6 -> 0.192 | P6: 3.09009 | Q6: 0.141321 | R6: =Q6*SQRT(M6) -> 0.39600076 | X6: =K6/I6 -> 0.28198184
A7: =E7/D7 -> 0.28198184 | B7: 0.89 | C7: =0.2*B7 -> 0.178 | D7: =I7*$B$9/$I$9 -> 1.1249813 | E7: =K7*$B$9/$I$9 -> 0.3172243 | F7: 1.121 (5+) | G7: 0d5/2, 5+ | H7: =N7*P7 -> 2.7501801 | I7: =H7*$H$29 -> 8.924386 | K7: =I7*SQRT(POWER(($I$29/$H$29),2)+POWER((R7/P7),2)+POWER((O7/N7),2)) -> 2.5165148 | L7: 86.3717 | M7: 7.85197 | N7: 0.89 | O7: =0.2*N7 -> 0.178 | P7: 3.09009 | Q7: 0.141321 | R7: =Q7*SQRT(M7) -> 0.39600076 | X7: =K7/I7 -> 0.28198184
A8: =E8/D8 -> 0.62713138 | B8: 0.21 | C8: =0.2*B8 -> 0.042 | D8: =I8*$B$9/$I$9 -> 0.063662409 | E8: =K8*$B$9/$I$9 -> 0.039924694 | F8: 3.062 (2+) | G8: 1s1/2, 2+ | H8: ='18F norm Option 1'!G6 -> 0.155632 | I8: ='18F norm Option 1'!H6 -> 0.50502876 | J8: ='18F norm Option 1'!I6 -> 0.0542378 | K8: ='18F norm Option 1'!J6 -> 0.31671938 | L8: ='18F norm Option 1'!K6 -> 24.3851 | M8: ='18F norm Option 1'!L6 -> 3.04813 | S8: free fit | X8: =K8/I8 -> 0.62713138
A9: =E9/D9 -> 0.20907278 | B9: 0.62 | C9: =0.2*B9 -> 0.124 | D9: =I9*$B$9/$I$9 -> 0.62 | E9: =K9*$B$9/$I$9 -> 0.12962513 | G9: 0d5/2, 2+ | H9: ='18F norm Option 1'!G7 -> 1.51568 | I9: ='18F norm Option 1'!H7 -> 4.91841 | J9: ='18F norm Option 1'!I7 -> 0.124664 | K9: ='18F norm Option 1'!O7 -> 1.0283057 | L9: ='18F norm Option 1'!K7 -> 24.3851 | M9: ='18F norm Option 1'!L7 -> 3.04813 | X9: =K9/I9 -> 0.20907278
F10: 3.727 (1+) 3.839 (2+) | G10: 1s1/2, 2+ | K10: =J10*SQRT(M10) -> 0 | S10: no data in literature on these states
G11: 0d5/2, 2+ | K11: =J11*SQRT(M11) -> 0
A12: =E12/D12 -> 0.33530197 | B12: 0.17 | C12: =0.2*B12 -> 0.034 | D12: =I12*$B$9/$I$9 -> 0.14737313 | E12: =K12*$B$9/$I$9 -> 0.049414499 | F12: 4.115 (3+) | G12: 1s1/2, 3+ | H12: ='18F norm Option 1'!G10 -> 0.360275 | I12: =H12*$H$29 -> 1.1690991 | J12: ='18F norm Option 1'!I10 -> 0.0693713 | K12: ='18F norm Option 1'!J10 -> 0.39200124 | L12: ='18F norm Option 1'!K10 -> 14.4574 | M12: ='18F norm Option 1'!L10 -> 2.40956 | S12: free fit | X12: =K12/I12 -> 0.33530197
A13: =E13/D13 -> 0.17942645 | B13: 0.68 | C13: =0.2*B13 -> 0.136 | D13: =I13*$B$9/$I$9 -> 0.77927056 | E13: =K13*$B$9/$I$9 -> 0.13982175 | G13: 0d5/2, 3+ | H13: ='18F norm Option 1'!G11 -> 1.90504 | I13: =H13*$H$29 -> 6.1818905 | J13: ='18F norm Option 1'!I11 -> 0.117092 | K13: ='18F norm Option 1'!J11 -> 1.1091947 | L13: ='18F norm Option 1'!K11 -> 14.4574 | M13: ='18F norm Option 1'!L11 -> 2.40956 | X13: =K13/I13 -> 0.17942645
A14: =E14/D14 -> 0.3358942 | B14: 0.074 | C14: =0.2*B14 -> 0.0148 | D14: =I14*$B$9/$I$9 -> 0.17371969 | E14: =K14*$B$9/$I$9 -> 0.058351436 | F14: 4.360 (1+) | G14: 0d5/2, 1+ | H14: ='18F norm Option 1'!G12 -> 0.424683 | I14: =H14*$H$29 -> 1.3781043 | J14: ='18F norm Option 1'!I12 -> 0.085519 | K14: ='18F norm Option 1'!J12 -> 0.46289724 | L14: ='18F norm Option 1'!K12 -> 11.0645 | M14: ='18F norm Option 1'!L12 -> 2.2129 | S14: free fit | X14: =K14/I14 -> 0.3358942
A15: =E15/D15 -> 0.26734311 | B15: 1.04 | C15: =0.2*B15 -> 0.208 | D15: =I15*$B$9/$I$9 -> 0.88432826 | E15: =K15*$B$9/$I$9 -> 0.23641907 | F15: 4.652 (4+) | G15: 0d5/2, 4+ | H15: =N15*P15 -> 2.1618688 | I15: =H15*$H$29 -> 7.0153048 | K15: =I15*SQRT(POWER(($I$29/$H$29),2)+POWER((R15/P15),2)+POWER((O15/N15),2)) -> 1.8754934 | L15: 55.6318 | M15: 7.9474 | N15: 1.04 | O15: =0.2*N15 -> 0.208 | P15: 2.07872 | Q15: 0.0675062 | R15: =Q15*SQRT(M15) -> 0.19030763 | S15: lit ratio from 17O(3He,d)18F | X15: =K15/I15 -> 0.26734311
A16: =E16/D16 -> 0.26734311 | B16: 0.18 | C16: =0.2*B16 -> 0.036 | D16: =I16*$B$9/$I$9 -> 0.15305681 | E16: =K16*$B$9/$I$9 -> 0.040918684 | F16: 4.753 (0+) | G16: 0d5/2, 0+ | H16: =N16*P16 -> 0.3741696 | I16: =H16*$H$29 -> 1.2141874 | K16: =I16*SQRT(POWER(($I$29/$H$29),2)+POWER((R16/P16),2)+POWER((O16/N16),2)) -> 0.32460462 | L16: 55.6318 | M16: 7.9474 | N16: 0.18 | O16: =0.2*N16 -> 0.036 | P16: 2.07872 | Q16: 0.0675062 | R16: =Q16*SQRT(M16) -> 0.19030763 | X16: =K16/I16 -> 0.26734311
A17: =E17/D17 -> 0.39872153 | B17: 0.17 | C17: =0.2*B17 -> 0.034 | D17: =I17*$B$9/$I$9 -> 0.15681294 | E17: =K17*$B$9/$I$9 -> 0.062524696 | F17: 4.964 (2+) | G17: 1s1/2, 2+ | H17: ='18F norm Option 1'!G14 -> 0.383352 | I17: ='18F norm Option 1'!H14 -> 1.2439844 | J17: ='18F norm Option 1'!I14 -> 0.0931427 | K17: ='18F norm Option 1'!J14 -> 0.49600337 | L17: ='18F norm Option 1'!K14 -> 13.8112 | M17: ='18F norm Option 1'!L14 -> 2.30186 | S17: free fit | X17: =K17/I17 -> 0.39872153
A18: =E18/D18 -> 0.21669168 | B18: 0.51 | C18: =0.2*B18 -> 0.102 | D18: =I18*$B$9/$I$9 -> 0.47113995 | E18: =K18*$B$9/$I$9 -> 0.10209211 | G18: 0d5/2, 2+ | H18: ='18F norm Option 1'!G15 -> 1.15177 | I18: ='18F norm Option 1'!H15 -> 3.7375152 | J18: ='18F norm Option 1'!I15 -> 0.117274 | K18: ='18F norm Option 1'!J15 -> 0.80988844 | L18: ='18F norm Option 1'!K15 -> 13.8112 | M18: ='18F norm Option 1'!L15 -> 2.30186 | X18: =K18/I18 -> 0.21669168
F19: 6.136 (0+) | G19: 0d5/2, 0+ | H19: =0.2*1.42 -> 0.284 | I19: =H19*$H$29 -> 0.92158532 | K19: =I19*SQRT(POWER(($I$29/$H$29),2)+POWER((R19/P19),2)+POWER((O19/N19),2)) -> 0.25725006 | L19: 13.728 | M19: 2.74559 | N19: 0.16 | O19: =0.2*N19 -> 0.032 | P19: 2.40521 | Q19: 0.176754 | R19: =Q19*SQRT(M19) -> 0.29287823 | S19: relative values like for the 5.340 0+ and 5.375 3+ states in 18O (IAS) | X19: =K19/I19 -> 0.27913863
F20: 6.163 (3+) | G20: 1s1/2, 3+ | H20: =0.75*1.42 -> 1.065 | I20: =H20*$H$29 -> 3.455945 | K20: =I20*SQRT(POWER(($I$29/$H$29),2)+POWER((R20/P20),2)+POWER((O20/N20),2)) -> 0.96468772 | L20: 13.728 | M20: 2.74559 | N20: 1.01 | O20: =0.2*N20 -> 0.202 | P20: 2.40521 | Q20: 0.176754 | R20: =Q20*SQRT(M20) -> 0.29287823 | X20: =K20/I20 -> 0.27913863
F21: 6.283 (2+) | G21: 1s1/2, 2+ | H21: 0 | I21: =H21*$H$29 -> 0 | K21: =I21*SQRT(POWER(($I$29/$H$29),2)+POWER((R21/P21),2)+POWER((O21/N21),2)) -> 0 | L21: 13.728 | M21: 2.74559 | N21: 0.35 | O21: =0.2*N21 -> 0.07 | P21: 2.40521 | Q21: 0.176754 | R21: =Q21*SQRT(M21) -> 0.29287823
F22: some energy | G22: 1p3/2, 3- | H22: 0.03
F23: 6.633 6.643 | G23: 1f7/2, 2- | H23: ='18F norm Option 1'!G20 -> 0.804098 | I23: ='18F norm Option 1'!H20 -> 3.6530383 | J23: ='18F norm Option 1'!I20 -> 0.103809 | K23: ='18F norm Option 1'!J20 -> 0.79755575 | L23: ='18F norm Option 1'!K20 -> 1.25024 | M23: ='18F norm Option 1'!L20 -> 0.250049 | S23: free fit | X23: =K23/I23 -> 0.21832669
D24: =I24*$B$9/$I$9 -> 0.24543439 | F24: 6.136 & 6.163 | G24: 0d5/2 | H24: 0.6 | I24: =H24*H29 -> 1.9470112
A25: =E25/D25 -> 0.23525718 | D25: =I25*$B$9/$I$9 -> 0.84183997 | E25: =K25*$B$9/$I$9 -> 0.1980489 | G25: 1s1/2 | H25: =1.47*H34 -> 2.058 | I25: =H25*H29 -> 6.6782486 | J25: =0.16 -> 0.16 | K25: =I25*SQRT(POWER((J25/1.47),2)+POWER((I34/H34),2)+POWER((I29/H29),2)) -> 1.5711059 | X25: =K25/I25 -> 0.23525718
F28: norm factor | H28: norm factor 2 | I28: unc norm factor 2
F29: 3.6014014 | H29: ='18F norm Option 1'!G23 -> 3.2450187 | I29: ='18F norm Option 1'!H23 -> 0.4931026
F30: SF with literature ratios | H30: SF free fit
H33: epsilon | I33: unc eps
H34: 1.4 | I34: 0.2
I39: need to fix the unc of unbound states

Sheet 18O & 18F
G1: 18O | N1: 18F
G2: Experiment | I2: SM | J2: Exp re-norm | K2: Exp re-norm unc | N2: Experiment | P2: SM | Q2: Exp re-norm | R2: Exp re-norm unc | S2: SF literature | T2: SF lit | U2: unc frac | V2: weighted diff
C3: literature | D3: unc (15%) | E3: lit norm | G3: SF norm (Opt 2 lit) | H3: unc final (including sqrt(chi2/ndf) and lit. Uncertainty | I3: SM SF | N3: SF norm (Opt 2 lit) | O3: unc final (including sqrt(chi2/ndf) and lit. Uncertainty | P3: SM SF
M4: 0d3/2, 1+ | N4: ='18F norm Option 2 lit'!I3 -> 7.4353114 | O4: ='18F norm Option 2 lit'!K3 -> 1.2880555 | P4: 0.1853 | Q4: =N4*$P$12/$N$12 -> 0.86803577 | R4: =O4*$P$12/$N$12 -> 0.15037409 | U4: =O4/N4 -> 0.17323491
A5: 0.0 (0+) | B5: 0d5/2, 0+ | C5: 1.22 | D5: =0.15*C5 -> 0.183 | E5: =$G$12/$C$12*C5 -> 7.2294701 | F5: =0.15*E5 -> 1.0844205 | G5: ='18O Option 2 lit'!G3 -> 6.19606 | H5: ='18O Option 2 lit'!I3 -> 0.84551641 | I5: 1.5448 | J5: =G5*$I$12/$G$12 -> 1.5478781 | K5: =H5*$I$12/$G$12 -> 0.21122395 | L5: 0.0 | M5: 0d5/2, 1+ | P5: 0.3164
L6: 0.937 (3+) | M6: 1s1/2, 3+ | N6: ='18F norm Option 2 lit'!I4 -> 1.0227948 | O6: ='18F norm Option 2 lit'!K4 -> 0.28840956 | P6: 0.3211 | Q6: =N6*$P$12/$N$12 -> 0.11940623 | R6: =O6*$P$12/$N$12 -> 0.033670388 | S6: 0.102 | T6: =$N$12/$S$12*S6 -> 0.80915777 | U6: =O6/N6 -> 0.28198184
M7: 1d3/2, 3+ | O7: ='18F norm Option 2 lit'!K5 -> 0.86522869 | P7: 0.0294 | R7: =O7*$P$12/$N$12 -> 0.10101116 | T7: =$N$12/$S$12*S7 -> 0
M8: 1d5/2, 3+ | N8: ='18F norm Option 2 lit'!I5 -> 3.0683844 | O8: ='18F norm Option 2 lit'!K5 -> 0.86522869 | P8: 0.264 | Q8: =N8*$P$12/$N$12 -> 0.35821868 | R8: =O8*$P$12/$N$12 -> 0.10101116 | S8: 0.306 | T8: =$N$12/$S$12*S8 -> 2.4274733 | U8: =O8/N8 -> 0.28198184 | W8: ratio | X8: unc
L9: 1.042 (0+) | M9: 0d5/2, 0+ | N9: ='18F norm Option 2 lit'!I6 -> 9.626304 | O9: ='18F norm Option 2 lit'!K6 -> 2.7144429 | P9: 0.7514 | Q9: =N9*$P$12/$N$12 -> 1.1238233 | R9: =O9*$P$12/$N$12 -> 0.31689777 | S9: 0.96 | T9: =$N$12/$S$12*S9 -> 7.6156026 | U9: =O9/N9 -> 0.28198184 | V9: =(G5-N9)/SQRT(H5*H5+O9*O9) -> -1.2065243 | W9: =N9/G5 -> 1.553617
L10: 1.121 (5+) | M10: 0d5/2, 5+ | N10: ='18F norm Option 2 lit'!I7 -> 8.924386 | O10: ='18F norm Option 2 lit'!K7 -> 2.5165148 | P10: 1 | Q10: =N10*$P$12/$N$12 -> 1.0418778 | R10: =O10*$P$12/$N$12 -> 0.29379064 | S10: 0.89 | T10: =$N$12/$S$12*S10 -> 7.0602982 | U10: =O10/N10 -> 0.28198184
A11: 1.982 (2+) | B11: 1s1/2, 2+ | C11: 0.21 | D11: =0.15*C11 -> 0.0315 | E11: =$G$12/$C$12*C11 -> 1.244417 | F11: =0.15*E11 -> 0.18666255 | G11: ='18O Option 2 lit'!G4 -> 0.743254 | H11: ='18O Option 2 lit'!I4 -> 0.10717148 | I11: 0.3282 | J11: =G11*$I$12/$G$12 -> 0.18567712 | K11: =H11*$I$12/$G$12 -> 0.026773205 | L11: 3.062 (2+) | M11: 1s1/2, 2+ | N11: ='18F norm Option 2 lit'!I8 -> 0.50502876 | O11: ='18F norm Option 2 lit'!K8 -> 0.31671938 | P11: 0.1471 | Q11: =N11*$P$12/$N$12 -> 0.058959605 | R11: =O11*$P$12/$N$12 -> 0.036975418 | S11: 0.21 | T11: =$N$12/$S$12*S11 -> 1.6659131 | U11: =O11/N11 -> 0.62713138 | V11: =(G11-N11)/SQRT(H11*H11+O11*O11) -> 0.71248039 | W11: =N11/G11 -> 0.6794834 | X11: =W11*SQRT(POWER((O11/N11),2)+POWER((H11/G11),2)) -> 0.43724383
B12: 0d5/2, 2+ | C12: 0.83 | D12: =0.15*C12 -> 0.1245 | E12: =$G$12/$C$12*C12 -> 4.91841 | F12: =0.15*E12 -> 0.7377615 | G12: ='18O Option 2 lit'!G5 -> 4.91841 | H12: ='18O Option 2 lit'!I5 -> 0.24445529 | I12: 1.2287 | J12: =G12*$I$12/$G$12 -> 1.2287 | K12: =H12*$I$12/$G$12 -> 0.061068967 | M12: 0d5/2, 2+ | N12: ='18F norm Option 2 lit'!I9 -> 4.91841 | O12: ='18F norm Option 2 lit'!K9 -> 1.0283057 | P12: 0.5742 | Q12: =N12*$P$12/$N$12 -> 0.5742 | R12: =O12*$P$12/$N$12 -> 0.12004959 | S12: 0.62 | T12: =$N$12/$S$12*S12 -> 4.91841 | U12: =O12/N12 -> 0.20907278 | V12: =(G12-N12)/SQRT(H12*H12+O12*O12) -> 0 | W12: =N12/G12 -> 1 | X12: =W12*SQRT(POWER((O12/N12),2)+POWER((H12/G12),2)) -> 0.21489934
L13: 3.727 (1+) | M13: 0d3/2, 1+ | P13: 0.087 | Y13: no information on these states in literature, so i took the 'Option 1' (free fit) values
M14: 0d5/2, 1+ | P14: 0.0987
L15: 3.839 (2+) | M15: 1s1/2, 2+ | N15: ='18F norm Option 1'!H8 -> 2.2567191 | O15: ='18F norm Option 1'!J8 -> 0.49585054 | P15: 0.3356 | Q15: =N15*$P$12/$N$12 -> 0.26346077 | R15: =O15*$P$12/$N$12 -> 0.057888094 | U15: =O15/N15 -> 0.21972187
M16: 0d3/2, 2+ | P16: 0.0703
M17: 0d5/2, 2+ | N17: ='18F norm Option 1'!H9 -> 4.4950649 | O17: ='18F norm Option 1'!J9 -> 0.95576303 | P17: 0.0095 | Q17: =N17*$P$12/$N$12 -> 0.52477655 | R17: =O17*$P$12/$N$12 -> 0.1115806 | U17: =O17/N17 -> 0.21262497
L18: 4.115 (3+) | M18: 1s1/2, 3+ | N18: ='18F norm Option 2 lit'!I12 -> 1.1690991 | O18: ='18F norm Option 2 lit'!K12 -> 0.39200124 | P18: 0.1379 | Q18: =N18*$P$12/$N$12 -> 0.13648653 | R18: =O18*$P$12/$N$12 -> 0.045764202 | S18: 0.17 | T18: =$N$12/$S$12*S18 -> 1.3485963 | U18: =O18/N18 -> 0.33530197
M19: 0d3/2, 3+ | P19: 0.0144
M20: 0d5/2, 3+ | N20: ='18F norm Option 2 lit'!I13 -> 6.1818905 | O20: ='18F norm Option 2 lit'!K13 -> 1.1091947 | P20: 0.6527 | Q20: =N20*$P$12/$N$12 -> 0.72170509 | R20: =O20*$P$12/$N$12 -> 0.12949298 | S20: 0.68 | T20: =$N$12/$S$12*S20 -> 5.3943852 | U20: =O20/N20 -> 0.17942645
M21: 0d3/2, 1+ | P21: 0.1908
L22: 4.360 (1+) | M22: 0d5/2, 1+ | N22: ='18F norm Option 2 lit'!I14 -> 1.3781043 | O22: ='18F norm Option 2 lit'!K14 -> 0.46289724 | P22: 0.186 | Q22: =N22*$P$12/$N$12 -> 0.16088685 | R22: =O22*$P$12/$N$12 -> 0.054040959 | S22: 0.074 | T22: =$N$12/$S$12*S22 -> 0.58703603 | U22: =O22/N22 -> 0.3358942
L23: 4.652 (4+) | M23: 0d3/2, 4+ | P23: 0.0349
A24: 3.552 (4+) | B24: 0d5/2, 4+ | C24: 1.57 | D24: =0.15*C24 -> 0.2355 | E24: =$G$12/$C$12*C24 -> 9.3034984 | F24: =0.15*E24 -> 1.3955248 | G24: ='18O Option 2 lit'!G6 -> 8.2684207 | H24: ='18O Option 2 lit'!I6 -> 1.3220241 | I24: 1.8598 | J24: =G24*$I$12/$G$12 -> 2.065588 | K24: =H24*$I$12/$G$12 -> 0.33026344 | M24: 0d5/2, 4+ | N24: ='18F norm Option 2 lit'!I15 -> 7.0153048 | O24: ='18F norm Option 2 lit'!K15 -> 1.8754934 | P24: 0.9241 | Q24: =N24*$P$12/$N$12 -> 0.81900207 | R24: =O24*$P$12/$N$12 -> 0.21895456 | S24: 1.04 | T24: =$N$12/$S$12*S24 -> 8.2502361 | U24: =O24/N24 -> 0.26734311 | V24: =(G24-N24)/SQRT(H24*H24+O24*O24) -> 0.54611344 | W24: =N24/G24 -> 0.84844555 | X24: =W24*SQRT(POWER((O24/N24),2)+POWER((H24/G24),2)) -> 0.26429674
A25: 3.630 (0+) | B25: 0d5/2, 0+ | C25: 0.28 | D25: =0.15*C25 -> 0.042 | E25: =$G$12/$C$12*C25 -> 1.6592227 | F25: =0.15*E25 -> 0.2488834 | G25: ='18O Option 2 lit'!G7 -> 1.4746228 | H25: ='18O Option 2 lit'!I7 -> 0.235775 | J25: =G25*$I$12/$G$12 -> 0.36838512 | K25: =H25*$I$12/$G$12 -> 0.058900486 | L25: 4.753 (0+) | M25: 0d5/2, 0+ | N25: ='18F norm Option 2 lit'!I16 -> 1.2141874 | O25: ='18F norm Option 2 lit'!K16 -> 0.32460462 | P25: 0.1794 | Q25: =N25*$P$12/$N$12 -> 0.14175036 | R25: =O25*$P$12/$N$12 -> 0.037895982 | S25: 0.18 | T25: =$N$12/$S$12*S25 -> 1.4279255 | U25: =O25/N25 -> 0.26734311 | V25: =(G25-N25)/SQRT(H25*H25+O25*O25) -> 0.64914808 | W25: =N25/G25 -> 0.82338844 | X25: =W25*SQRT(POWER((O25/N25),2)+POWER((H25/G25),2)) -> 0.25649127
A26: 3.920 (2+) | B26: 1s1/2, 2+ | C26: 0.35 | D26: =0.15*C26 -> 0.0525 | E26: =$G$12/$C$12*C26 -> 2.0740283 | F26: =0.15*E26 -> 0.31110425 | G26: ='18O Option 2 lit'!G8 -> 1.26514 | H26: ='18O Option 2 lit'!I8 -> 0.43678576 | I26: 0.6208 | J26: =G26*$I$12/$G$12 -> 0.31605285 | K26: =H26*$I$12/$G$12 -> 0.10911629 | L26: 4.964 (2+) | M26: 1s1/2, 2+ | N26: ='18F norm Option 2 lit'!I17 -> 1.2439844 | O26: ='18F norm Option 2 lit'!K17 -> 0.49600337 | P26: 0.337 | Q26: =N26*$P$12/$N$12 -> 0.14522902 | R26: =O26*$P$12/$N$12 -> 0.057905936 | S26: 0.17 | T26: =$N$12/$S$12*S26 -> 1.3485963 | U26: =O26/N26 -> 0.39872153 | V26: =(G26-N26)/SQRT(H26*H26+O26*O26) -> 0.032009802 | W26: =N26/G26 -> 0.98327807 | X26: =W26*SQRT(POWER((O26/N26),2)+POWER((H26/G26),2)) -> 0.51860283
B27: 0d5/2, 2+ | C27: 0.66 | D27: =0.15*C27 -> 0.099 | E27: =$G$12/$C$12*C27 -> 3.9110248 | F27: =0.15*E27 -> 0.58665372 | G27: ='18O Option 2 lit'!G9 -> 3.48609 | H27: ='18O Option 2 lit'!I9 -> 0.55106233 | I27: 0.7274 | J27: =G27*$I$12/$G$12 -> 0.87088282 | K27: =H27*$I$12/$G$12 -> 0.13766446 | M27: 0d5/2, 2+ | N27: ='18F norm Option 2 lit'!I18 -> 3.7375152 | O27: ='18F norm Option 2 lit'!K18 -> 0.80988844 | P27: 0.3924 | Q27: =N27*$P$12/$N$12 -> 0.43633639 | R27: =O27*$P$12/$N$12 -> 0.094550462 | S27: 0.51 | T27: =$N$12/$S$12*S27 -> 4.0457889 | U27: =O27/N27 -> 0.21669168 | V27: =(G27-N27)/SQRT(H27*H27+O27*O27) -> -0.25666475 | W27: =N27/G27 -> 1.0721224 | X27: =W27*SQRT(POWER((O27/N27),2)+POWER((H27/G27),2)) -> 0.28756647
A28: 5.255 (2+) | B28: 1s1/2, 2+ | C28: 0.35 | D28: =0.15*C28 -> 0.0525 | E28: =$G$12/$C$12*C28 -> 2.0740283 | F28: =0.15*E28 -> 0.31110425 | G28: ='18O Option 2 lit'!G10 -> 1.5525125 | H28: ='18O Option 2 lit'!I10 -> 0.24245368 | J28: =G28*$I$12/$G$12 -> 0.38784325 | K28: =H28*$I$12/$G$12 -> 0.060568931
B29: 0d3/2, 2+
B30: 0d5/2, 2+
A31: 5.340 (0+) | B31: 0d5/2, 0+ | C31: 0.16 | D31: =0.15*C31 -> 0.024 | E31: =$G$12/$C$12*C31 -> 0.94812723 | F31: =0.15*E31 -> 0.14221908 | G31: ='18O Option 2 lit'!G11 -> 0.70972 | H31: ='18O Option 2 lit'!I11 -> 0.11083597 | J31: =G31*$I$12/$G$12 -> 0.17729977 | K31: =H31*$I$12/$G$12 -> 0.027688654 | L31: 6.136 (0+) | M31: 0d5/2, 0+ | N31: ='18F norm Option 2 lit'!I24 -> 1.9470112 | O31: ='18F norm Option 2 lit'!K19 -> 0.25725006 | P31: 0.0692 | Q31: =N31*$P$12/$N$12 -> 0.22730392 | R31: =O31*$P$12/$N$12 -> 0.03003267 | U31: =O31/N31 -> 0.13212562 | V31: =(G31-N31)/SQRT(H31*H31+O31*O31) -> -4.4171453 | W31: =N31/G31 -> 2.7433512 | X31: =W31*SQRT(POWER((O31/N31),2)+POWER((H31/G31),2)) -> 0.56118671
A32: 5.375 (3+) | B32: 1s1/2, 3+ | C32: 1.01 | D32: =0.15*C32 -> 0.1515 | E32: =$G$12/$C$12*C32 -> 5.9850531 | F32: =0.15*E32 -> 0.89775797 | G32: ='18O Option 2 lit'!G12 -> 4.4801075 | H32: ='18O Option 2 lit'!I12 -> 0.69965204 | I32: 0.99 | J32: =G32*$I$12/$G$12 -> 1.1192048 | K32: =H32*$I$12/$G$12 -> 0.17478463 | M32: 1s1/2, 3+ | N32: ='18F norm Option 2 lit'!I25 -> 6.6782486 | O32: ='18F norm Option 2 lit'!K25 -> 1.5711059 | P32: 0.529 | Q32: =N32*$P$12/$N$12 -> 0.77965243 | R32: =O32*$P$12/$N$12 -> 0.18341884 | U32: =O32/N32 -> 0.23525718 | V32: =(G32-N32)/SQRT(H32*H32+O32*O32) -> -1.2780998 | W32: =N32/G32 -> 1.4906447 | X32: =W32*SQRT(POWER((O32/N32),2)+POWER((H32/G32),2)) -> 0.42091797
M33: 0d3/2, 3+ | P33: 0.0037
L34: 6.163 (3+) | M34: 0d5/2, 3+ | P34: 0.0003
L35: 6.283 (2+) | M35: 1s1/2, 2+ | N35: ='18F norm Option 2 lit'!I21 -> 0 | O35: ='18F norm Option 2 lit'!K21 -> 0 | R35: =O35*$P$12/$N$12 -> 0
L36: 6.633 6.643 | M36: 1f7/2, 2- | N36: ='18F norm Option 2 SM'!E28 -> 2.7525564 | O36: ='18F norm Option 2 SM'!F28 -> 0.103809 | Q36: =N36*$P$12/$N$12 -> 0.32134733 | R36: =O36*$P$12/$N$12 -> 0.012119186 | U36: =O36/N36 -> 0.037713668
A37: 6.200 (1-) | B37: 1p3/2, 1- | G37: ='18O Option 2 lit'!G13 -> 0.287743 | H37: ='18O Option 2 lit'!H13 -> 0.0363742 | J37: =G37*$I$12/$G$12 -> 0.071882951 | K37: =H37*$I$12/$G$12 -> 0.0090868755 | Q37: =N37*$P$12/$N$12 -> 0
B38: 0d3/2, 4+ | I38: 0.9299 | L38: 5.6 (ell=1) | N38: 0.2829 | Q38: =N38*$P$12/$N$12 -> 0.033027173
A39: 7.1 (4+) | B39: 0d5/2, 4+ | G39: ='18O Option 2 lit'!G14 -> 0.281672 | H39: ='18O Option 2 lit'!H14 -> 0.022748 | I39: 0.1402 | J39: =G39*$I$12/$G$12 -> 0.070366315 | K39: =H39*$I$12/$G$12 -> 0.0056828259 | L39: 5.6 (ell=0) | N39: 0.33 | Q39: =N39*$P$12/$N$12 -> 0.038525865
A42: comparing fits with Option 1 (maybe makes more sense since both states are ell=2 and cannot be separated)
...

Sheet 18F norm Option 2 SM
D2: SF | E2: SF norm | F2: unc | G2: chi2 | H2: chi2/ndf | I2: SM ratio | J2: norm | K2: unc | L2: comment
B3: 0.0 | C3: 0d3/2, 1+ | D3: 2.32702 | E3: =D3*$D$31 -> 7.9657627 | F3: 0.328425 | G3: 0.870116 | L3: free fit
B4: 0.937 (3+) | C4: 1s1/2, 3+ | D4: =I4*J4 -> 0.534776 | E4: =D4*$D$31 -> 1.830624 | F4: =I4*K4 -> 0.024061307 | G4: 158.193 | H4: 14.3811 | I4: 0.3211 | J4: 1.66545 | K4: 0.074934
C5: 1d3/2, 3+ | D5: =I5*J5 -> 0.04896423 | E5: =D5*$D$31 -> 0.16761241 | F5: =I5*K5 -> 0.0022030596 | G5: 158.193 | H5: 14.3811 | I5: 0.0294 | J5: 1.66545 | K5: 0.074934
C6: 1d5/2, 3+ | D6: =I6*J6 -> 0.4396788 | E6: =D6*$D$31 -> 1.5050911 | F6: =I6*K6 -> 0.019782576 | G6: 158.193 | H6: 14.3811 | I6: 0.264 | J6: 1.66545 | K6: 0.074934
B7: 1.042 (0+) | C7: 0d5/2, 0+ | D7: =I7*J7 -> 1.2514191 | E7: =D7*$D$31 -> 4.2838084 | F7: =I7*K7 -> 0.056305408 | G7: 158.193 | H7: 14.3811 | I7: 0.7514 | J7: 1.66545 | K7: 0.074934
B8: 1.121 (5+) | C8: 0d5/2, 5+ | D8: =I8*J8 -> 1.66545 | E8: =D8*$D$31 -> 5.7011025 | F8: =I8*K8 -> 0.074934 | G8: 158.193 | H8: 14.3811 | I8: 1 | J8: 1.66545 | K8: 0.074934
B9: 3.062 (2+) | C9: 1s1/2, 2+ | D9: 0.177364 | E9: =D9*$D$31 -> 0.60714542 | F9: 0.0446717 | G9: 31.5443 | H9: 4.37474 | L9: free fit
C10: 0d5/2, 2+ | D10: 1.45576 | E10: =D10*$D$31 -> 4.9833 | F10: 0.12048 | G10: 31.5443 | H10: 4.37474
B11: 3.727 (1+) | C11: 0d3/2, 1+ | D11: =I11*J11 -> 0.25210164 | E11: =D11*$D$31 -> 0.86298435 | F11: =I11*K11 -> 0.015407613 | G11: 21.9294 | H11: 2.74117 | I11: 0.087 | J11: 2.89772 | K11: 0.177099
C12: 0d5/2, 1+ | D12: =I12*J12 -> 0.28600496 | E12: =D12*$D$31 -> 0.97904087 | F12: =I12*K12 -> 0.017479671 | G12: 21.9294 | H12: 2.74117 | I12: 0.0987 | J12: 2.89772 | K12: 0.177099
B13: 3.839 (2+) | C13: 1s1/2, 2+ | D13: =I13*J13 -> 0.97247483 | E13: =D13*$D$31 -> 3.3289373 | F13: =I13*K13 -> 0.059434424 | G13: 21.9294 | H13: 2.74117 | I13: 0.3356 | J13: 2.89772 | K13: 0.177099
C14: 0d3/2, 2+ | D14: =I14*J14 -> 0.20370972 | E14: =D14*$D$31 -> 0.69733104 | F14: =I14*K14 -> 0.01245006 | G14: 21.9294 | H14: 2.74117 | I14: 0.0703 | J14: 2.89772 | K14: 0.177099
C15: 0d5/2, 2+ | D15: =I15*J15 -> 0.02752834 | E15: =D15*$D$31 -> 0.094233924 | F15: =I15*K15 -> 0.0016824405 | G15: 21.9294 | H15: 2.74117 | I15: 0.0095 | J15: 2.89772 | K15: 0.177099
B16: 4.115 (3+) | C16: 1s1/2, 3+ | D16: 0.36343 | E16: =D16*$D$31 -> 1.2440792 | F16: 0.0563932 | G16: 21.1067 | H16: 3.02854 | L16: free fit
C17: 0d5/2, 3+ | D17: 1.87075 | E17: =D17*$D$31 -> 6.4038773 | F17: 0.114702 | G17: 21.1067 | H17: 3.02854
B18: 4.360 (1+) | C18: 0d5/2, 1+ | D18: 0.457064 | E18: =D18*$D$31 -> 1.5646034 | F18: 0.0833332 | G18: 15.2321 | H18: 3.06196 | L18: free fit
B19: 4.652 (4+) | C19: 0d3/2, 4+ | D19: =I19*J19 -> 0.08084934 | E19: =D19*$D$31 -> 0.27676026 | F19: =I19*K19 -> 0.002443 | G19: 58.4586 | H19: 8.35123 | I19: 0.0349 | J19: 2.3166 | K19: 0.07
C20: 0d5/2, 4+ | D20: =I20*J20 -> 2.1407701 | E20: =D20*$D$31 -> 7.3281993 | F20: =I20*K20 -> 0.064687 | G20: 58.4586 | H20: 8.35123 | I20: 0.9241 | J20: 2.3166 | K20: 0.07
B21: 4.753 (0+) | C21: 0d5/2, 0+ | D21: =I21*J21 -> 0.41559804 | E21: =D21*$D$31 -> 1.4226588 | F21: =I21*K21 -> 0.012558 | G21: 58.4586 | H21: 8.35123 | I21: 0.1794 | J21: 2.3166 | K21: 0.07
B22: 4.964 (2+) | C22: 1s1/2, 2+ | D22: 0.439995 | E22: =D22*$D$31 -> 1.5061735 | F22: 0.078332 | G22: 17.8107 | H22: 4.02874 | L22: free fit
C23: 0d5/2, 2+ | D23: 1.13315 | E23: =D23*$D$31 -> 3.8789542 | F23: 0.112195 | G23: 17.8107 | H23: 4.02874
B24: 6.136 (0+) | C24: 0d5/2, 0+ | D24: =I24*J24 -> 0.38584674 | E24: =D24*$D$31 -> 1.3208153 | F24: =I24*K24 -> 0.028167168 | G24: 11.2664 | H24: 2.25328 | I24: 0.0692 | J24: 5.57582 | K24: 0.40704
C25: 1s1/2, 3+ | D25: =I25*J25 -> 2.9496088 | E25: =D25*$D$31 -> 10.096984 | F25: =I25*K25 -> 0.21532416 | G25: 11.2664 | H25: 2.25328 | I25: 0.529 | J25: 5.57582 | K25: 0.40704
C26: 0d3/2, 3+ | D26: =I26*J26 -> 0.020630534 | E26: =D26*$D$31 -> 0.070621627 | F26: =I26*K26 -> 0.001506048 | G26: 11.2664 | H26: 2.25328 | I26: 0.0037 | J26: 5.57582 | K26: 0.40704
B27: 6.163 (3+) | C27: 0d5/2, 3+ | D27: =I27*J27 -> 0.001672746 | E27: =D27*$D$31 -> 0.0057260779 | F27: =I27*K27 -> 0.000122112 | G27: 11.2664 | H27: 2.25328 | I27: 0.0003 | J27: 5.57582 | K27: 0.40704
B28: 6.633 6.643 | C28: 1f7/2, 2- | D28: 0.804098 | E28: =D28*D31 -> 2.7525564 | F28: 0.103809 | G28: 1.25024 | L28: free fit
B30: norm factor | D30: norm factor 2
B31: 3.6014014 | D31: 3.4231604
B32: SF with literature ratios | D32: SF free fit
B34: some of the states are not reproduced with SM so I wouldn't trust this too much

Sheet 6.136 MeV in 18F
B2: energy | C2: 6.1495 | D2: 5.8995 | E2: 5.6495 | F2: 5.3995 | G2: 5.1495 | H2: 4.8995 | I2: 4.6495 | J2: 4.3995 | K2: 4.1495 | L2: 3.8995 | M2: 3.6495
B3: 0d5/2, 0+ | C3: 0 | D3: 0 | E3: 0 | F3: 0.488629 | G3: 0.662279 | H3: 0.622943 | I3: 0.00326 | J3: 0 | K3: 0 | L3: 0 | M3: 0
B4: 1s1/2, 3+ | C4: 2.36506 | D4: 2.37955 | E4: 2.39464 | F4: 1.22179 | G4: 1.16235 | H4: 1.10592 | I4: 1.05311 | J4: 1.00722 | K4: 0.968247 | L4: 0.935308 | M4: 0.935308
B5: 1p3/2, 3- | C5: 0.273058 | D5: 0.273875 | E5: 0.274628 | F5: 0 | G5: 0 | H5: 0.0148281 | I5: 0.0673968 | J5: 0.0757607 | K5: 0.0838638 | L5: 0.0915794 | M5: 0.0915794
B6: unc s | F6: 0.16
B51: energy | C51: 6.1495 | D51: 5.8995 | E51: 5.6495 | F51: 5.3995 | G51: 5.1495 | H51: 4.8995 | I51: 4.6495 | J51: 4.3995 | K51: 4.1495 | L51: 3.8995 | M51: 3.6495
B52: 0d5/2, 0+ | C52: 1.04265 | D52: 1.04706 | E52: 1.05064 | F52: 0.497907 | G52: 0.662876 | H52: 0.834023 | I52: 1.00516 | J52: 1.16829 | K52: 1.33883 | L52: 1.51313 | M52: 1.68603
B53: 1s1/2, 3+ | C53: 2.55947 | D53: 2.57497 | E53: 2.59099 | F53: 1.22211 | G53: 1.16221 | H53: 1.10672 | I53: 1.05414 | J53: 1.007 | K53: 0.96 | L53: 0.93427 | M53: 0.899162
B54: unc d | C54: 0.27 | D54: 0.27 | E54: 0.27 | F54: 0.538 | G54: 0.54 | H54: 0.55789 | I54: 0.56 | J54: 0.58 | K54: 0.59 | L54: 0.61 | M54: 0.62984
B55: unc s | C55: 0.35 | D55: 0.36 | E55: 0.36 | F55: 0.165752 | G55: 0.158 | H55: 0.15 | I55: 0.1448 | J55: 0.1386 | K55: 0.133 | L55: 0.129 | M55: 0.126103
F65: =F69/F67 -> 0.13101331 | G65: =G69/G67 -> 0.13793103 | H65: =H69/H67 -> 0.13756528 | I65: =I69/I67 -> 0.13674305 | J65: =J69/J67 -> 0.13234973 | K65: =K69/K67 -> 0.13402062 | L65: =L69/L67 -> 0.13653461 | M65: =M69/M67 -> 0.13245033
B66: energy | C66: 6.1495 | D66: 5.8995 | E66: 5.6495 | F66: 5.3995 | G66: 5.1495 | H66: 4.8995 | I66: 4.6495 | J66: 4.3995 | K66: 4.1495 | L66: 3.8995 | M66: 3.6495
B67: 1s1/2, 3+ | C67: 2.36488 | D67: 2.379 | E67: 2.39496 | F67: 1.22125 | G67: 1.16 | H67: 1.10493 | I67: 1.05307 | J67: 1.00718 | K67: 0.97 | L67: 0.935294 | M67: 0.906
B68: 1p3/2, 3- | C68: 0.27 | D68: 0.27 | E68: 0.27 | F68: 0.0371182 | G68: 0.047 | H68: 0.058 | I68: 0.0676 | J68: 0.0758 | K68: 0.0838 | L68: 0.0915389 | M68: 0.098
B69: unc s | C69: 0.38 | D69: 0.38 | E69: 0.3848 | F69: 0.16 | G69: 0.16 | H69: 0.152 | I69: 0.144 | J69: 0.1333 | K69: 0.13 | L69: 0.1277 | M69: 0.12
B70: unc p | C70: 0.069 | D70: 0.069 | E70: 0.067 | F70: 0.04 | G70: 0.04 | H70: 0.039 | I70: 0.038 | J70: 0.037 | K70: 0.036 | L70: 0.036 | M70: 0.036
